<?xml version="1.0" ?>
<robot name="ugv" xmlns:xacro="http://www.ros.org/wiki/xacro">

    <xacro:include filename="$(find ugv_description)/urdf/materials.xacro"/>

    <link name="base_link">
        <inertial>
            <origin xyz="0.25539221363619424 -0.008191452128420306 0.07740258559841702" rpy="0 0 0"/>
            <mass value="1.8582255296411472"/>
            <inertia ixx="0.018307" iyy="0.036178" izz="0.054" ixy="-3e-06" iyz="-0.0" ixz="-5e-06"/>
        </inertial>
        <visual>
            <origin xyz="0 0 0" rpy="0 0 0"/>
            <geometry>
                <mesh filename="file://$(find ugv_description)/meshes/base_link.stl" scale="0.001 0.001 0.001"/>
            </geometry>
            <material name="silver"/>
        </visual>
        <collision>
            <origin xyz="0 0 0" rpy="0 0 0"/>
            <geometry>
                <mesh filename="file://$(find ugv_description)/meshes/base_link.stl" scale="0.001 0.001 0.001"/>
            </geometry>
        </collision>
    </link>

    <link name="lidar_link">
        <inertial>
            <origin xyz="-0.0001155547326693318 3.2715051849067412e-06 0.01794478211293804" rpy="0 0 0"/>
            <mass value="0.7886321015037847"/>
            <inertia ixx="0.000269" iyy="0.000272" izz="0.000333" ixy="0.0" iyz="0.0" ixz="-1e-06"/>
        </inertial>
        <visual>
            <origin xyz="-0.43536 6e-05 -0.091" rpy="0 0 0"/>
            <geometry>
                <mesh filename="file://$(find ugv_description)/meshes/lidar_link.stl" scale="0.001 0.001 0.001"/>
            </geometry>
            <material name="silver"/>
        </visual>
        <collision>
            <origin xyz="-0.43536 6e-05 -0.091" rpy="0 0 0"/>
            <geometry>
                <mesh filename="file://$(find ugv_description)/meshes/lidar_link.stl" scale="0.001 0.001 0.001"/>
            </geometry>
        </collision>
    </link>

    <link name="front_right_wheel">
        <inertial>
            <origin xyz="-3.129242420740752e-10 -0.018799999999999678 2.9802320333782717e-10" rpy="0 0 0"/>
            <mass value="1.4688367113110694"/>
            <inertia ixx="0.000755" iyy="0.001163" izz="0.000755" ixy="0.0" iyz="0.0" ixz="-0.0"/>
        </inertial>
        <visual>
            <origin xyz="-0.4007 0.1312 -0.0425" rpy="0 0 0"/>
            <geometry>
                <mesh filename="file://$(find ugv_description)/meshes/front_right_wheel.stl" scale="0.001 0.001 0.001"/>
            </geometry>
            <material name="silver"/>
        </visual>
        <collision>
            <origin xyz="-0.4007 0.1312 -0.0425" rpy="0 0 0"/>
            <geometry>
                <mesh filename="file://$(find ugv_description)/meshes/front_right_wheel.stl" scale="0.001 0.001 0.001"/>
            </geometry>
        </collision>
    </link>

    <link name="rear_right_wheel">
        <inertial>
            <origin xyz="-3.1292413105177275e-10 -0.018799999999999956 2.9802320333782717e-10" rpy="0 0 0"/>
            <mass value="1.4688367113110694"/>
            <inertia ixx="0.000755" iyy="0.001163" izz="0.000755" ixy="0.0" iyz="0.0" ixz="0.0"/>
        </inertial>
        <visual>
            <origin xyz="-0.1095 0.1312 -0.0425" rpy="0 0 0"/>
            <geometry>
                <mesh filename="file://$(find ugv_description)/meshes/rear_right_wheel.stl" scale="0.001 0.001 0.001"/>
            </geometry>
            <material name="silver"/>
        </visual>
        <collision>
            <origin xyz="-0.1095 0.1312 -0.0425" rpy="0 0 0"/>
            <geometry>
                <mesh filename="file://$(find ugv_description)/meshes/rear_right_wheel.stl" scale="0.001 0.001 0.001"/>
            </geometry>
        </collision>
    </link>

    <link name="rear_left_wheel">
        <inertial>
            <origin xyz="-3.129242143184996e-10 0.01880000000000008 2.980232241545089e-10" rpy="0 0 0"/>
            <mass value="1.4688367113110694"/>
            <inertia ixx="0.000755" iyy="0.001163" izz="0.000755" ixy="0.0" iyz="0.0" ixz="0.0"/>
        </inertial>
        <visual>
            <origin xyz="-0.1095 -0.1148 -0.0425" rpy="0 0 0"/>
            <geometry>
                <mesh filename="file://$(find ugv_description)/meshes/rear_left_wheel.stl" scale="0.001 0.001 0.001"/>
            </geometry>
            <material name="silver"/>
        </visual>
        <collision>
            <origin xyz="-0.1095 -0.1148 -0.0425" rpy="0 0 0"/>
            <geometry>
                <mesh filename="file://$(find ugv_description)/meshes/rear_left_wheel.stl" scale="0.001 0.001 0.001"/>
            </geometry>
        </collision>
    </link>

    <link name="front_left_wheel">
        <inertial>
            <origin xyz="-3.1292435309637767e-10 0.018800000000000303 2.980232241545089e-10" rpy="0 0 0"/>
            <mass value="1.4688367113110694"/>
            <inertia ixx="0.000755" iyy="0.001163" izz="0.000755" ixy="0.0" iyz="0.0" ixz="0.0"/>
        </inertial>
        <visual>
            <origin xyz="-0.4007 -0.1148 -0.0425" rpy="0 0 0"/>
            <geometry>
                <mesh filename="file://$(find ugv_description)/meshes/front_left_wheel.stl" scale="0.001 0.001 0.001"/>
            </geometry>
            <material name="silver"/>
        </visual>
        <collision>
            <origin xyz="-0.4007 -0.1148 -0.0425" rpy="0 0 0"/>
            <geometry>
                <mesh filename="file://$(find ugv_description)/meshes/front_left_wheel.stl" scale="0.001 0.001 0.001"/>
            </geometry>
        </collision>
    </link>

    <joint name="lidar_link_joint" type="fixed">
        <origin xyz="0.43536 -6e-05 0.091" rpy="0 0 0"/>
        <parent link="base_link"/>
        <child link="lidar_link"/>
    </joint>

    <joint name="front_right_wheel_joint" type="continuous">
        <origin xyz="0.4007 -0.1312 0.0425" rpy="0 0 0"/>
        <parent link="base_link"/>
        <child link="front_right_wheel"/>
        <axis xyz="-0.0 1.0 -0.0"/>
    </joint>

    <joint name="rear_right_wheel_joint" type="continuous">
        <origin xyz="0.1095 -0.1312 0.0425" rpy="0 0 0"/>
        <parent link="base_link"/>
        <child link="rear_right_wheel"/>
        <axis xyz="-0.0 1.0 0.0"/>
    </joint>

    <joint name="rear_left_wheel_joint" type="continuous">
        <origin xyz="0.1095 0.1148 0.0425" rpy="0 0 0"/>
        <parent link="base_link"/>
        <child link="rear_left_wheel"/>
        <axis xyz="0.0 1.0 0.0"/>
    </joint>

    <joint name="front_left_wheel_joint" type="continuous">
        <origin xyz="0.4007 0.1148 0.0425" rpy="0 0 0"/>
        <parent link="base_link"/>
        <child link="front_left_wheel"/>
        <axis xyz="0.0 1.0 0.0"/>
    </joint>
    
    <link name="base_footprint"/>

    <joint name="base_footprint_joint" type="fixed">
        <parent link="base_link"/>
        <child link="base_footprint"/>
        <origin xyz="0 0 0" rpy="0 0 0"/>
    </joint>

</robot>
